Workbook

Sheet ①基本設定
A1: VaR 逐步計算驗證 — 基本設定（v2）
A3: ▌ 資產與部位定義
A4: 資產名稱 | B4: 市場 | C4: 幣別 | D4: 持有數量 | E4: 最新本地價格 | F4: 即期匯率(→TWD) | G4: TWD 市值（G列） | H4: 占組合比重
A5: 台積電(2330.TW) | B5: 台灣 🇹🇼 | C5: TWD | D5: 1000 | E5: 858.34 | F5: 1 | G5: 858340 | H5: 0.44940267
A6: AAPL | B6: 美國 🇺🇸 | C6: USD | D6: 100 | E6: 322.48 | F6: 32.269 | G6: 1040599 | H6: 0.54482871
A7: 三星(005930.KS) | B7: 韓國 🇰🇷 | C7: KRW | D7: 10 | E7: 44775.73 | F7: 0.0246 | G7: 11018 | H7: 0.0057686192
F8: 組合總市值(TWD) | G8: 1909957
A9: ★ G5:G7（TWD 市值）會被 Sheet 3 P&L 公式直接引用，請勿移動此欄位置。
A11: ▌ VaR 計算參數
A12: 信賴水準 α | B12: 99%
A13: 持有天數 h | B13: 1 日
A14: 歷史回溯天數 T | B14: 250 個交易日
A15: 回報方式 | B15: 對數回報 ln(P_t / P_{t-1})
A16: FX 調整 | B16: 外幣資產：r_adj = r_local + r_FX（對數精確分解）
A17: z_α | B17: =@NORM.S.INV(0.99) =2.32634787404084
A18: VaR 分位索引（HS） | B18: idx = floor((1-α)×T) = floor(0.01×250) = 2
A19: HS VaR 公式 | B19: -P&L_sorted[2] （第 3 小損益）
A20: HS CVaR 公式 | B20: -mean(P&L_sorted[0:2]) （最差 2 筆均值）
A21: MC 模擬路徑數 | B21: 5,000
A23: ▌ 即期匯率（計算時使用）
A24: 幣別 | B24: 匯率（1 外幣 = ? TWD） | C24: 說明
A25: TWD | B25: 1 | C25: 基礎幣別（不動）
A26: USD | B26: 32.26896 | C26: 美元/台幣
A27: KRW | B27: 0.02461 | C27: 韓元/台幣

Sheet ②原始價格與FX
A1: 原始收盤價 & FX 匯率歷史（本地幣別，純數值）
A2: 日期 | B2: 台積電(TWD) | C2: AAPL(USD) | D2: 三星(KRW) | F2: 日期 | G2: USD/TWD | H2: KRW/TWD
A3: 2024-01-16 | B3: 600 | C3: 185 | D3: 70000 | F3: 2024-01-16 | G3: 32.5 | H3: 0.0235
A4: 2024-01-17 | B4: 612.96 | C4: 191.48 | D4: 72532 | F4: 2024-01-17 | G4: 32.4404 | H4: 0.0236
A5: 2024-01-18 | B5: 601.63 | C5: 186.11 | D5: 71998 | F5: 2024-01-18 | G5: 32.3249 | H5: 0.023592
A6: 2024-01-19 | B6: 612.57 | C6: 188.75 | D6: 75291 | F6: 2024-01-19 | G6: 32.3576 | H6: 0.023439
A7: 2024-01-22 | B7: 622.34 | C7: 191.75 | D7: 74596 | F7: 2024-01-22 | G7: 32.3261 | H7: 0.023492
A8: 2024-01-23 | B8: 609.19 | C8: 195.66 | D8: 74763 | F8: 2024-01-23 | G8: 32.2454 | H8: 0.023428
A9: 2024-01-24 | B9: 619.66 | C9: 192.06 | D9: 74007 | F9: 2024-01-24 | G9: 32.3271 | H9: 0.023693
A10: 2024-01-25 | B10: 604.34 | C10: 188.34 | D10: 74843 | F10: 2024-01-25 | G10: 32.265 | H10: 0.023738
A11: 2024-01-26 | B11: 587.18 | C11: 185.26 | D11: 74514 | F11: 2024-01-26 | G11: 32.2032 | H11: 0.023885
A12: 2024-01-29 | B12: 579.84 | C12: 183.92 | D12: 73921 | F12: 2024-01-29 | G12: 32.1483 | H12: 0.023907
A13: 2024-01-30 | B13: 585.18 | C13: 183.11 | D13: 74413 | F13: 2024-01-30 | G13: 32.2658 | H13: 0.023806
A14: 2024-01-31 | B14: 586.32 | C14: 184.63 | D14: 74950 | F14: 2024-01-31 | G14: 32.3219 | H14: 0.023781
... A253: 2024-12-31 | B253: 858.34 | C253: 322.48 | D253: 44776 | F253: 2024-12-31 | G253: 32.269 | H253: 0.024607
A254: 共 251 列（含黃色初始列 S0）。B欄=台積電 TWD，C欄=AAPL USD，D欄=三星 KRW，G欄=USD/TWD，H欄=KRW/TWD。

Sheet ③回報計算FX調整
A1: 步驟一：計算對數回報 & FX 調整（公式直接引用 Sheet 2）
A3: ▌ 公式說明
A4: B欄 台積電 r_local
A5: C欄 AAPL r_local
A6: D欄 三星 r_local
A7: E欄 USD r_FX
A8: F欄 KRW r_FX
A9: G欄 台積電 r_adj
A10: H欄 AAPL r_adj
A11: I欄 三星 r_adj
A12: J欄 組合P&L
A13: 驗證方法 | B13: J欄 P&L = Σ(r_adj_i × MV_i)，與 Sheet4 HS VaR 計算的基礎相同
A14: ▌ 回報序列（250 個交易日，全為 Excel 公式）
A15: 日期 | B15: 台積電 r_local | C15: AAPL r_local | D15: 三星 r_local | E15: USD r_FX | F15: KRW r_FX | G15: 台積電 r_adj | H15: AAPL r_adj | I15: 三星 r_adj | J15: 組合P&L(TWD)
A16: 2024-01-17 | B16: =LN(②原始價格與FX!B4/②原始價格與FX!B3) -> 0.021370026 | C16: =LN(②原始價格與FX!C4/②原始價格與FX!C3) -> 0.034427539 | D16: =LN(②原始價格與FX!D4/②原始價格與FX!D3) -> 0.035532602 | E16: =LN(②原始價格與FX!G4/②原始價格與FX!G3) -> -0.0018355297 | F16: =LN(②原始價格與FX!H4/②原始價格與FX!H3) -> 0.0042462909 | G16: =B16 -> 0.021370026 | H16: =C16+E16 -> 0.03259201 | I16: =D16+F16 -> 0.039778893 | J16: =G16*①基本設定!$G$5+H16*①基本設定!$G$6+I16*①基本設定!$G$7 -> 52696.244
A17: 2024-01-18 | B17: =LN(②原始價格與FX!B5/②原始價格與FX!B4) -> -0.018657043 | C17: =LN(②原始價格與FX!C5/②原始價格與FX!C4) -> -0.028445468 | D17: =LN(②原始價格與FX!D5/②原始價格與FX!D4) -> -0.0073895029 | E17: =LN(②原始價格與FX!G5/②原始價格與FX!G4) -> -0.0035667286 | F17: =LN(②原始價格與FX!H5/②原始價格與FX!H4) -> -0.00033904052 | G17: =B17 -> -0.018657043 | H17: =C17+E17 -> -0.032012196 | I17: =D17+F17 -> -0.0077285435 | J17: =G17*①基本設定!$G$5+H17*①基本設定!$G$6+I17*①基本設定!$G$7 -> -49411.098
A18: 2024-01-19 | B18: =LN(②原始價格與FX!B6/②原始價格與FX!B5) -> 0.018020583 | C18: =LN(②原始價格與FX!C6/②原始價格與FX!C5) -> 0.014085491 | D18: =LN(②原始價格與FX!D6/②原始價格與FX!D5) -> 0.044722265 | E18: =LN(②原始價格與FX!G6/②原始價格與FX!G5) -> 0.0010110927 | F18: =LN(②原始價格與FX!H6/②原始價格與FX!H5) -> -0.0065063698 | G18: =B18 -> 0.018020583 | H18: =C18+E18 -> 0.015096584 | I18: =D18+F18 -> 0.038215895 | J18: =G18*①基本設定!$G$5+H18*①基本設定!$G$6+I18*①基本設定!$G$7 -> 31598.34
A19: 2024-01-22 | B19: =LN(②原始價格與FX!B7/②原始價格與FX!B6) -> 0.015823346 | C19: =LN(②原始價格與FX!C7/②原始價格與FX!C6) -> 0.015769052 | D19: =LN(②原始價格與FX!D7/②原始價格與FX!D6) -> -0.0092737193 | E19: =LN(②原始價格與FX!G7/②原始價格與FX!G6) -> -0.00097397034 | F19: =LN(②原始價格與FX!H7/②原始價格與FX!H6) -> 0.002258636 | G19: =B19 -> 0.015823346 | H19: =C19+E19 -> 0.014795082 | I19: =D19+F19 -> -0.0070150833 | J19: =G19*①基本設定!$G$5+H19*①基本設定!$G$6+I19*①基本設定!$G$7 -> 28900.266
A20: 2024-01-23 | B20: =LN(②原始價格與FX!B8/②原始價格與FX!B7) -> -0.021356361 | C20: =LN(②原始價格與FX!C8/②原始價格與FX!C7) -> 0.020186019 | D20: =LN(②原始價格與FX!D8/②原始價格與FX!D7) -> 0.0022362237 | E20: =LN(②原始價格與FX!G8/②原始價格與FX!G7) -> -0.0024995561 | F20: =LN(②原始價格與FX!H8/②原始價格與FX!H7) -> -0.0027280494 | G20: =B20 -> -0.021356361 | H20: =C20+E20 -> 0.017686463 | I20: =D20+F20 -> -0.00049182571 | J20: =G20*①基本設定!$G$5+H20*①基本設定!$G$6+I20*①基本設定!$G$7 -> 68.077353
A21: 2024-01-24 | B21: =LN(②原始價格與FX!B9/②原始價格與FX!B8) -> 0.017040735 | C21: =LN(②原始價格與FX!C9/②原始價格與FX!C8) -> -0.018570636 | D21: =LN(②原始價格與FX!D9/②原始價格與FX!D8) -> -0.010163427 | E21: =LN(②原始價格與FX!G9/②原始價格與FX!G8) -> 0.0025304903 | F21: =LN(②原始價格與FX!H9/②原始價格與FX!H8) -> 0.011247758 | G21: =B21 -> 0.017040735 | H21: =C21+E21 -> -0.016040145 | I21: =D21+F21 -> 0.0010843308 | J21: =G21*①基本設定!$G$5+H21*①基本設定!$G$6+I21*①基本設定!$G$7 -> -2052.6681
A22: 2024-01-25 | B22: =LN(②原始價格與FX!B10/②原始價格與FX!B9) -> -0.025033987 | C22: =LN(②原始價格與FX!C10/②原始價格與FX!C9) -> -0.019558983 | D22: =LN(②原始價格與FX!D10/②原始價格與FX!D9) -> 0.011232903 | E22: =LN(②原始價格與FX!G10/②原始價格與FX!G9) -> -0.0019228364 | F22: =LN(②原始價格與FX!H10/②原始價格與FX!H9) -> 0.0018974938 | G22: =B22 -> -0.025033987 | H22: =C22+E22 -> -0.021481819 | I22: =D22+F22 -> 0.013130397 | J22: =G22*①基本設定!$G$5+H22*①基本設定!$G$6+I22*①基本設定!$G$7 -> -43696.962
A23: 2024-01-26 | B23: =LN(②原始價格與FX!B11/②原始價格與FX!B10) -> -0.028805537 | C23: =LN(②原始價格與FX!C11/②原始價格與FX!C10) -> -0.016488596 | D23: =LN(②原始價格與FX!D11/②原始價格與FX!D10) -> -0.0044055589 | E23: =LN(②原始價格與FX!G11/②原始價格與FX!G10) -> -0.0019172249 | F23: =LN(②原始價格與FX!H11/②原始價格與FX!H10) -> 0.0061735072 | G23: =B23 -> -0.028805537 | H23: =C23+E23 -> -0.018405821 | I23: =D23+F23 -> 0.0017679483 | J23: =G23*①基本設定!$G$5+H23*①基本設定!$G$6+I23*①基本設定!$G$7 -> -43858.544
A24: 2024-01-29 | B24: =LN(②原始價格與FX!B12/②原始價格與FX!B11) -> -0.012579213 | C24: =LN(②原始價格與FX!C12/②原始價格與FX!C11) -> -0.0072593634 | D24: =LN(②原始價格與FX!D12/②原始價格與FX!D11) -> -0.0079900718 | E24: =LN(②原始價格與FX!G12/②原始價格與FX!G11) -> -0.0017062543 | F24: =LN(②原始價格與FX!H12/②原始價格與FX!H11) -> 0.00092065624 | G24: =B24 -> -0.012579213 | H24: =C24+E24 -> -0.0089656177 | I24: =D24+F24 -> -0.0070694156 | J24: =G24*①基本設定!$G$5+H24*①基本設定!$G$6+I24*①基本設定!$G$7 -> -20204.746
A25: 2024-01-30 | B25: =LN(②原始價格與FX!B13/②原始價格與FX!B12) -> 0.0091672888 | C25: =LN(②原始價格與FX!C13/②原始價格與FX!C12) -> -0.0044138153 | D25: =LN(②原始價格與FX!D13/②原始價格與FX!D12) -> 0.0066337024 | E25: =LN(②原始價格與FX!G13/②原始價格與FX!G12) -> 0.0036482736 | F25: =LN(②原始價格與FX!H13/②原始價格與FX!H12) -> -0.0042336533 | G25: =B25 -> 0.0091672888 | H25: =C25+E25 -> -0.0007655417 | I25: =D25+F25 -> 0.002400049 | J25: =G25*①基本設定!$G$5+H25*①基本設定!$G$6+I25*①基本設定!$G$7 -> 7098.4725
A26: 2024-01-31 | B26: =LN(②原始價格與FX!B14/②原始價格與FX!B13) -> 0.0019462234 | C26: =LN(②原始價格與FX!C14/②原始價格與FX!C13) -> 0.0082667573 | D26: =LN(②原始價格與FX!D14/②原始價格與FX!D13) -> 0.0071905668 | E26: =LN(②原始價格與FX!G14/②原始價格與FX!G13) -> 0.0017371733 | F26: =LN(②原始價格與FX!H14/②原始價格與FX!H13) -> -0.0010507072 | G26: =B26 -> 0.0019462234 | H26: =C26+E26 -> 0.010003931 | I26: =D26+F26 -> 0.0061398596 | J26: =G26*①基本設定!$G$5+H26*①基本設定!$G$6+I26*①基本設定!$G$7 -> 12148.251
A27: 2024-02-01 | B27: =LN(②原始價格與FX!B15/②原始價格與FX!B14) -> 0.033954422 | C27: =LN(②原始價格與FX!C15/②原始價格與FX!C14) -> -0.0017346998 | D27: =LN(②原始價格與FX!D15/②原始價格與FX!D14) -> 0.03091154 | E27: =LN(②原始價格與FX!G15/②原始價格與FX!G14) -> -0.0051428508 | F27: =LN(②原始價格與FX!H15/②原始價格與FX!H14) -> -0.0023997485 | G27: =B27 -> 0.033954422 | H27: =C27+E27 -> -0.0068775506 | I27: =D27+F27 -> 0.028511792 | J27: =G27*①基本設定!$G$5+H27*①基本設定!$G$6+I27*①基本設定!$G$7 -> 22301.81
... A265: 2024-12-31 | B265: =LN(②原始價格與FX!B253/②原始價格與FX!B252) -> -0.0064220031 | C265: =LN(②原始價格與FX!C253/②原始價格與FX!C252) -> -0.036506071 | D265: =LN(②原始價格與FX!D253/②原始價格與FX!D252) -> 0.00604827 | E265: =LN(②原始價格與FX!G253/②原始價格與FX!G252) -> -0.00085184817 | F265: =LN(②原始價格與FX!H253/②原始價格與FX!H252) -> -0.0042984657 | G265: =B265 -> -0.0064220031 | H265: =C265+E265 -> -0.037357919 | I265: =D265+F265 -> 0.0017498044 | J265: =G265*①基本設定!$G$5+H265*①基本設定!$G$6+I265*①基本設定!$G$7 -> -44367.596
A267: 平均 | G267: =AVERAGE(G16:G265) -> 0.0014322825 | H267: =AVERAGE(H16:H265) -> 0.0021942089 | I267: =AVERAGE(I16:I265) -> -0.0016031697 | J267: =AVERAGE(J16:J265) -> 3495.0132
A268: 標準差 | G268: =STDEV(G16:G265) -> 0.01964812 | H268: =STDEV(H16:H265) -> 0.019023139 | I268: =STDEV(I16:I265) -> 0.021962455 | J268: =STDEV(J16:J265) -> 29629.803
A270: 藍色格（H, I）= FX 已疊加。P&L 負值（紅色）共 112 筆。所有數值均為 Excel 公式，可點入儲存格確認計算鏈。

Sheet ④HS歷史模擬法
A1: 步驟二（HS）：歷史模擬法 VaR 逐步計算
A3: ▌ 方法說明 & 公式
A4: Step 1 | B4: 取 T=250 個交易日的 FX 調整後組合損益（直接引用 Sheet 3 J 欄）
A5: Step 2 | B5: 將 T 筆損益由小到大排序（B欄=時序，H欄=排序，使用 SMALL() 公式）
A6: Step 3 | B6: 取第 3 小的損益作為 -VaR idx = floor((1-α)×T) = floor(0.01×250) = 2
A7: Step 4 | B7: VaR = -SMALL(P&L, 3) ← 見結果區公式
A8: Step 5 | B8: CVaR = -AVERAGE(SMALL(P&L,1),...,SMALL(P&L,2)) ← 最差 2 筆均值
A9: 驗證 | B9: 點擊任意 H 欄（排序）或結果格，確認公式引用自 Sheet 3
A11: ▌ 組合損益序列 & 排序（T=250，全為公式引用）
A12: ▶ 原始損益（時間序列，引用 Sheet 3 J 欄） | F12: ▶ 排序後損益（由小到大，使用 SMALL() 公式）
A13: 排名 | B13: 日期 | C13: 原始P&L（引用Sheet3） | F13: 排名 | G13: 排序P&L＝SMALL() | H13: 說明
A14: 1 | B14: 2024-01-17 | C14: =③回報計算FX調整!J16 -> 52696.244 | F14: 1 | G14: =SMALL(③回報計算FX調整!$J$16:$J$265,1) -> -79153.236 | H14: ← CVaR 範圍
A15: 2 | B15: 2024-01-18 | C15: =③回報計算FX調整!J17 -> -49411.098 | F15: 2 | G15: =SMALL(③回報計算FX調整!$J$16:$J$265,2) -> -58300.353 | H15: ← CVaR 範圍
A16: 3 | B16: 2024-01-19 | C16: =③回報計算FX調整!J18 -> 31598.34 | F16: 3 | G16: =SMALL(③回報計算FX調整!$J$16:$J$265,3) -> -52728.708 | H16: ← VaR 點（第 3 小）
A17: 4 | B17: 2024-01-22 | C17: =③回報計算FX調整!J19 -> 28900.266 | F17: 4 | G17: =SMALL(③回報計算FX調整!$J$16:$J$265,4) -> -52018.438
A18: 5 | B18: 2024-01-23 | C18: =③回報計算FX調整!J20 -> 68.077353 | F18: 5 | G18: =SMALL(③回報計算FX調整!$J$16:$J$265,5) -> -51113.728
A19: 6 | B19: 2024-01-24 | C19: =③回報計算FX調整!J21 -> -2052.6681 | F19: 6 | G19: =SMALL(③回報計算FX調整!$J$16:$J$265,6) -> -49411.098
A20: 7 | B20: 2024-01-25 | C20: =③回報計算FX調整!J22 -> -43696.962 | F20: 7 | G20: =SMALL(③回報計算FX調整!$J$16:$J$265,7) -> -48273.986
A21: 8 | B21: 2024-01-26 | C21: =③回報計算FX調整!J23 -> -43858.544 | F21: 8 | G21: =SMALL(③回報計算FX調整!$J$16:$J$265,8) -> -46763.646
A22: 9 | B22: 2024-01-29 | C22: =③回報計算FX調整!J24 -> -20204.746 | F22: 9 | G22: =SMALL(③回報計算FX調整!$J$16:$J$265,9) -> -46079.89
A23: 10 | B23: 2024-01-30 | C23: =③回報計算FX調整!J25 -> 7098.4725 | F23: 10 | G23: =SMALL(③回報計算FX調整!$J$16:$J$265,10) -> -46072.359
A24: 11 | B24: 2024-01-31 | C24: =③回報計算FX調整!J26 -> 12148.251 | F24: 11 | G24: =SMALL(③回報計算FX調整!$J$16:$J$265,11) -> -45899.325
A25: 12 | B25: 2024-02-01 | C25: =③回報計算FX調整!J27 -> 22301.81 | F25: 12 | G25: =SMALL(③回報計算FX調整!$J$16:$J$265,12) -> -44879.758
A26: 13 | B26: 2024-02-02 | C26: =③回報計算FX調整!J28 -> -24648.763 | F26: 13 | G26: =SMALL(③回報計算FX調整!$J$16:$J$265,13) -> -44367.596
A27: 14 | B27: 2024-02-05 | C27: =③回報計算FX調整!J29 -> -13149.809 | F27: 14 | G27: =SMALL(③回報計算FX調整!$J$16:$J$265,14) -> -43967.453
A28: 15 | B28: 2024-02-06 | C28: =③回報計算FX調整!J30 -> -34783.717 | F28: 15 | G28: =SMALL(③回報計算FX調整!$J$16:$J$265,15) -> -43878.53
A29: 16 | B29: 2024-02-07 | C29: =③回報計算FX調整!J31 -> 58888.724 | F29: 16 | G29: =SMALL(③回報計算FX調整!$J$16:$J$265,16) -> -43858.544
A30: 17 | B30: 2024-02-08 | C30: =③回報計算FX調整!J32 -> -19341.7 | F30: 17 | G30: =SMALL(③回報計算FX調整!$J$16:$J$265,17) -> -43696.962
A31: 18 | B31: 2024-02-09 | C31: =③回報計算FX調整!J33 -> -3388.2118 | F31: 18 | G31: =SMALL(③回報計算FX調整!$J$16:$J$265,18) -> -40062.167
A32: 19 | B32: 2024-02-12 | C32: =③回報計算FX調整!J34 -> 39020.206 | F32: 19 | G32: =SMALL(③回報計算FX調整!$J$16:$J$265,19) -> -38514.416
A33: 20 | B33: 2024-02-13 | C33: =③回報計算FX調整!J35 -> 11655.577 | F33: 20 | G33: =SMALL(③回報計算FX調整!$J$16:$J$265,20) -> -37048.168
A34: 21 | B34: 2024-02-14 | C34: =③回報計算FX調整!J36 -> -27453.138 | F34: 21 | G34: =SMALL(③回報計算FX調整!$J$16:$J$265,21) -> -34966.559
A35: 22 | B35: 2024-02-15 | C35: =③回報計算FX調整!J37 -> -23992.454 | F35: 22 | G35: =SMALL(③回報計算FX調整!$J$16:$J$265,22) -> -34783.717
A36: 23 | B36: 2024-02-16 | C36: =③回報計算FX調整!J38 -> 4206.6692 | F36: 23 | G36: =SMALL(③回報計算FX調整!$J$16:$J$265,23) -> -34110.939
A37: 24 | B37: 2024-02-19 | C37: =③回報計算FX調整!J39 -> -16423.726 | F37: 24 | G37: =SMALL(③回報計算FX調整!$J$16:$J$265,24) -> -33913.704
A38: 25 | B38: 2024-02-20 | C38: =③回報計算FX調整!J40 -> 52557.772 | F38: 25 | G38: =SMALL(③回報計算FX調整!$J$16:$J$265,25) -> -33826.567
A39: 26 | B39: 2024-02-21 | C39: =③回報計算FX調整!J41 -> 34733.775 | F39: 26 | G39: =SMALL(③回報計算FX調整!$J$16:$J$265,26) -> -33046.359
A40: 27 | B40: 2024-02-22 | C40: =③回報計算FX調整!J42 -> -11424.76 | F40: 27 | G40: =SMALL(③回報計算FX調整!$J$16:$J$265,27) -> -32664.163
A41: 28 | B41: 2024-02-23 | C41: =③回報計算FX調整!J43 -> 23348.433 | F41: 28 | G41: =SMALL(③回報計算FX調整!$J$16:$J$265,28) -> -31853.751
A42: 29 | B42: 2024-02-26 | C42: =③回報計算FX調整!J44 -> 25164.479 | F42: 29 | G42: =SMALL(③回報計算FX調整!$J$16:$J$265,29) -> -31477.648
...

Sheet ⑤參數法Parametric
A1: 步驟三（Parametric）：Delta-Normal VaR 逐步計算
A3: ▌ 方法說明 & 公式
A4: Step 1 | B4: 計算 FX 調整後回報的樣本共變異數矩陣 Σ（基於 T=250 筆回報）
A5: Step 2 | B5: 組合方差：σ²_P = w'Σw，w = TWD 市值向量
A6: Step 3 | B6: 組合日標準差：σ_P = √(w'Σw) = 29,631.2436 TWD
A7: Step 4 | B7: z_α = NORM.S.INV(0.99) = 2.326348
A8: Step 5 | B8: VaR = z_α × σ_P = 2.3263 × 29,631.2436 = 68,932.58 TWD
A9: Step 6 | B9: CVaR = φ(z_α)/(1-α) × σ_P = 0.026652/0.01 × 29,631.2436 = 78,973.61 TWD
A10: Step 7 | B10: Component VaR_i = w_i × (Σw)_i / σ_P × z_α ← 精確可加分解
A11: 驗證 | B11: Σ Component VaR_i = Portfolio VaR（代數精確，見下方驗證列）
A13: ▌ 共變異數矩陣 Σ（樣本）
B14: 台積電(2330.TW) | C14: AAPL | D14: 三星(005930.KS)
A15: 台積電(2330.TW) | B15: 0.0003860204 | C15: 0.000111121 | D15: 5.3999e-05
A16: AAPL | B16: 0.000111121 | C16: 0.0003619692 | D16: 9.02743e-05
A17: 三星(005930.KS) | B17: 5.3999e-05 | C17: 9.02743e-05 | D17: 0.0004823625
A19: ▌ 相關係數矩陣 ρ
B20: 台積電(2330.TW) | C20: AAPL | D20: 三星(005930.KS)
A21: 台積電(2330.TW) | B21: 1 | C21: 0.2973 | D21: 0.1251
A22: AAPL | B22: 0.2973 | C22: 1 | D22: 0.216
A23: 三星(005930.KS) | B23: 0.1251 | C23: 0.216 | D23: 1
A25: ▌ σ_P 計算步驟（w'Σw）
A26: 資產 | B26: w（TWD 市值） | C26: Σw（= Σ×w 第 i 元素） | D26: w_i × (Σw)_i | E26: 加總 = σ²_P
A27: 台積電(2330.TW) | B27: 858340 | C27: 447.56408 | D27: 3.8416206e+08
A28: AAPL | B28: 1040599 | C28: 473.03917 | D28: 4.922443e+08
A29: 三星(005930.KS) | B29: 11018 | C29: 145.6034 | D29: 1604231.3
A30: 加總 = σ²_P | D30: 8.7801059e+08
A31: √σ²_P = σ_P (TWD) | D31: 29631.244
A33: ▌ Parametric 計算結果
A34: 項目 | B34: 公式 | C34: 數值
A35: z_α | B35: NORM.S.INV(0.99) | C35: 2.326348
A36: σ_P（日，TWD） | B36: √(w'Σw) | C36: 29631.244
A37: VaR（TWD） | B37: z_α × σ_P | C37: 68932.58
A38: CVaR（TWD） | B38: φ(z_α)/(1-α) × σ_P | C38: 78973.61
A39: VaR% | B39: VaR / 組合市值 | C39: 0.036091
A40: CVaR/VaR | B40: CVaR / VaR | C40: 1.145665
A42: ▌ Component VaR（精確可加分解驗證）
A43: 資產 | B43: w_i (TWD) | C43: (Σw)_i/σ_P | D43: Marginal VaR | E43: Component VaR | F43: Component CVaR | G43: 風險貢獻%
A44: 台積電(2330.TW) | B44: 858340 | C44: 0.01510447 | D44: 0.03513824 | E44: 30160.55 | F44: 34553.87 | G44: 0.4375
A45: AAPL | B45: 1040599 | C45: 0.0159642 | D45: 0.03713829 | E45: 38646.08 | F45: 44275.45 | G45: 0.5606
A46: 三星(005930.KS) | B46: 11018 | C46: 0.00491385 | D46: 0.01143132 | E46: 125.95 | F46: 144.29 | G46: 0.0018
...

Sheet ⑥Monte Carlo模擬
A1: 步驟四（MC）：蒙地卡羅法 VaR（5,000 條路徑）
A3: ▌ 方法說明 & 公式
A4: Step 1 | B4: 估計 FX 調整後回報的共變異數矩陣 Σ（同參數法）
A5: Step 2 | B5: 對 Σ 進行 Cholesky 分解：Σ = L L'（L 為下三角矩陣）
A6: Step 3 | B6: 模擬 M=5,000 組相關常態亂數：r_sim = L×z + μ，z ~ N(0,I)
A7: Step 4 | B7: 各路徑損益：P&L_k = Σ_i w_i × r_sim(k,i)
A8: Step 5 | B8: VaR = -PERCENTILE(P&L, 1%) = 66,135.64 TWD
A9: Step 6 | B9: CVaR = -mean(P&L[P&L ≤ -VaR]) = 74,402.65 TWD
A11: ▌ Cholesky 分解 L（手算步驟）
B12: L[i,0] | C12: L[i,1] | D12: L[i,2] | E12: 計算公式
A13: 台積電(2330.TW) | B13: 0.019647401 | C13: — | D13: — | E13: L[0,0] = √Σ[0,0]
A14: AAPL | B14: 0.005655762 | C14: 0.018165395 | D14: — | E14: L[1,0]=Σ[1,0]/L[0,0]；L[1,1]=√(Σ[1,1]−L[1,0]²)
A15: 三星(005930.KS) | B15: 0.002748402 | C15: 0.004113864 | D15: 0.021398246 | E15: L[2,0]=Σ[2,0]/L[0,0]；L[2,1]=(Σ[2,1]−L[2,0]×L[1,0])/L[1,1]；L[2,2]=√(Σ[2,2]−L[2,0]²−L[2,1]²)
A17: ▌ 驗證 Cholesky：L × L' 應還原 Σ
B18: 台積電(2330.TW) | C18: AAPL | D18: 三星(005930.KS)
A19: 台積電(2330.TW) | B19: 0.0003860204 | C19: 0.000111121 | D19: 5.3999e-05
A20: AAPL | B20: 0.000111121 | C20: 0.0003619692 | D20: 9.02743e-05
A21: 三星(005930.KS) | B21: 5.3999e-05 | C21: 9.02743e-05 | D21: 0.0004823625
A22: ✓ 各格與 Σ 差距 < 1e-10（數值機器精度），驗證 Cholesky 正確。
A24: ▌ 前 50 條模擬路徑（共 5,000 條）
A25: 路徑# | B25: r_sim[TSMC] | C25: r_sim[AAPL] | D25: r_sim[三星] | E25: P&L (TWD) | F25: 例外?
A26: 1 | B26: 0.007419 | C26: -0.014974 | D26: 0.011014 | E26: -9092.56
A27: 2 | B27: 0.019912 | C27: -0.027928 | D27: -0.034909 | E27: -12354.8
A28: 3 | B28: 0.003944 | C28: -0.002827 | D28: -0.002912 | E28: 410.95
A29: 4 | B29: -0.015328 | C29: 0.013344 | D29: 0.016313 | E29: 909.19
A30: 5 | B30: 0.00273 | C30: 0.023044 | D30: 0.013219 | E30: 26468.58
A31: 6 | B31: -0.015451 | C31: 0.004033 | D31: -0.022966 | E31: -9318.45
A32: 7 | B32: 0.018692 | C32: 0.006256 | D32: -0.00335 | E32: 22516.31
A33: 8 | B33: -0.011946 | C33: 0.020551 | D33: -0.001752 | E33: 11112.08
A34: 9 | B34: -0.006983 | C34: -0.006625 | D34: 0.007161 | E34: -12809.07
A35: 10 | B35: 0.008612 | C35: 0.011758 | D35: 0.010318 | E35: 19741.84
A36: 11 | B36: 0.04351 | C36: 0.006924 | D36: -0.00835 | E36: 44459.68
A37: 12 | B37: -0.014556 | C37: 0.008781 | D37: 0.022852 | E37: -3104.74
... A75: 50 | B75: -0.001334 | C75: 0.020762 | D75: 0.005756 | E75: 20523.24
A77: 僅展示前 50 條路徑，完整 5,000 條用於計算 VaR/CVaR。
A79: ▌ MC 計算結果
A80: MC VaR（TWD） | B80: 66135.64 | C80: -PERCENTILE(P&L, 1%)
A81: MC CVaR（TWD） | B81: 74402.65 | C81: −mean(P&L[P&L ≤ −VaR])
A82: VaR%（占市值） | B82: 0.034627 | C82: VaR / 組合市值
A83: CVaR/VaR | B83: 1.125001 | C83: CVaR / VaR
...

Sheet ⑦三法彙總比較
A1: 三方法 VaR 彙總比較 & 驗證核對表
A3: ▌ 組合層級指標比較
A4: 指標 | B4: Historical Simulation | C4: Parametric Delta-Normal | D4: Monte Carlo（M=5,000） | E4: 說明
A5: VaR（TWD） | B5: 52735.256 | C5: 68932.58 | D5: 66135.644 | E5: 主要風險指標
A6: CVaR（TWD） | B6: 68722.302 | C6: 78973.612 | D6: 74402.645 | E6: 一致性風險測度
A7: VaR%（占市值） | B7: 0.0276 | C7: 0.0361 | D7: 0.0346 | E7: 相對風險水準
A8: CVaR / VaR | B8: 1.3032 | C8: 1.1457 | D8: 1.125 | E8: 尾端形狀（常態≈1.29）
A9: 損益標準差（TWD） | B9: 29571.922 | C9: 29631.244 | D9: 29868.076 | E9: 1日組合損益σ
A11: ▌ 個別資產 Component VaR 比較（TWD）
A12: 資產 | B12: 市場 | C12: 幣別 | D12: HS VaR | E12: Param VaR | F12: MC VaR | G12: HS 貢獻% | H12: Param 貢獻% | I12: MC 貢獻%
A13: 台積電(2330.TW) | B13: 台灣 🇹🇼 | C13: TWD | D13: 37369.67 | E13: 30160.55 | F13: 38488.62 | G13: 0.7086 | H13: 0.4375 | I13: 0.582
A14: AAPL | B14: 美國 🇺🇸 | C14: USD | D14: 37181.89 | E14: 38646.08 | F14: 43723.62 | G14: 0.7051 | H14: 0.5606 | I14: 0.6611
A15: 三星(005930.KS) | B15: 韓國 🇰🇷 | C15: KRW | D15: 598.82 | E15: 125.95 | F15: 586.56 | G15: 0.0114 | H15: 0.0018 | I15: 0.0089
A17: ▌ 驗證核對表
A18: 驗證項目 | B18: HS | C18: Parametric | D18: Monte Carlo | E18: 預期結果 | F18: 通過?
A19: Component VaR 加總 = 組合 VaR | B19: 75,150 ≠ 52,735（近似） | C19: 68,933 ≈ 68,933（精確） | D19: 82,799 ≠ 66,136（近似） | E19: HS/MC 近似；Parametric 代數精確 | F19: Param ✓
A20: CVaR > VaR | B20: ✓ | C20: ✓ | D20: ✓ | E20: 必然成立（定義性質） | F20: ✓
A21: VaR > 0 | B21: ✓ | C21: ✓ | D21: ✓ | E21: 正常市場必然 | F21: ✓
A22: MC → Parametric 收斂 | B22: — | C22: 68,933 | D22: 66,136（差 4.1%） | E22: 大樣本下 MC ≈ Param（同常態假設） | F22: ✓
A24: 資料期間：2024-01-16 ~ 2024-12-31，T=250，N_MC=5,000，α=99%，h=1日。
